Workbook
Name Slicer_Match_Confidence: #N/A
Name Slicer_Month: #N/A
Name Slicer_Standardized_Item: #N/A

Sheet Read Me
A2: Food Price Trends & Inflation
A3: Selected Food Prices — Nigeria, November 2024 to April 2025
A4: Prepared from the Selected Food Price Watch dataset, standardized across a Jan-2025 item-list change.
A5: 1. National Price Trend
A6: Summing the 33 items tracked continuously across all six months, the total basket rose from ₦84,423 in November 2024 to ₦95,788 in April 2025 — a 13.5% increase over five months, roughly 2.5% per month compounded.
A7: The rise wasn't a straight line. Prices climbed steadily through March, then eased slightly in April (₦97,158 → ₦95,788) — the only month-over-month dip in the entire window.
A8: Month | B8: Basket Total (₦)
A9: 45597 | B9: 84423
A10: 45627 | B10: 85881
A11: 45658 | B11: 89710
A12: 45689 | B12: 91022
A13: 45717 | B13: 97158
A14: 45748 | B14: 95788
A16: 2. Inflation Is Not Evenly Spread Across Food Groups
A17: Average year-on-year (YoY) inflation varies sharply by category as of April 2025:
A18: Category | B18: Avg YoY %
A19: Staples (rice, beans, garri, yam, plantain) | B19: 0.997
A20: Fish / seafood | B20: 0.875
A21: Processed / dairy | B21: 0.744
A22: Meat / poultry / eggs | B22: 0.738
A23: Cooking oils | B23: 0.719
A24: Vegetables / fruit | B24: 0.621
A26: Staples effectively doubled year-on-year. This is the most consequential finding in the dataset. Staples form the base of most Nigerian households' calorie intake and are the least substitutable food group, so this is where inflation is felt hardest — particularly by low-income households.
A27: 3. A Small Set of Items Is Driving Volatility
A28: Local Rice (Broken), Beans (Brown & White), Plantain, and Yam Tuber lead YoY inflation at 114–158%, all staples, consistent with the finding above.
A29: Separately, Onions and Agric Hen Eggs (crate of 30) are the most volatile items month-to-month (standard deviation of MoM change of roughly 27% and 17% respectively). These swing sharply rather than trending steadily — a supply-chain and perishability signature rather than a structural inflation one.
A30: 4. Geography Matters More Than Expected
A31: The average gap between a food's highest-priced state and its lowest-priced state is 123% — the median gap is exactly 100%, meaning for a typical item in a typical month, the price simply doubles between the cheapest and most expensive state.
A32: Item | B32: Avg State Price Gap
A33: Onions, fresh | B33: 3.02
A34: Agric Hen Eggs (crate of 30) | B34: 2.67
A35: Sweet potatoes | B35: 2.59
A36: Mudfish, dried | B36: 2.47
A37: Tomatoes, fresh | B37: 2.09
A39: Northeastern states (Yobe, Borno, Adamawa, Taraba, Gombe, Bauchi) appear as the lowest-price state 91 times across the dataset, versus only 34 times as the highest-price state. This is consistent with these being production zones where the crop is grown, but transport and insecurity constraints limit onward distribution — the price gap reflects logistics friction more than production cost.
A40: 5. Recommendations
A41: On the April price dip
A42: Treat the April easing with caution in any report. One month is not a trend reversal, and it follows five consecutive months of increases. It should be described as “stabilizing” rather than “improving” until May/June data confirms the direction.
A43: On food security framing
A44: The staples finding, not the volatile perishables, is the headline. A roughly 100% YoY increase in rice, beans, and yam affects nutrition security more than a volatile onion price, because households can skip onions for a week but not staples. Any policy-facing summary of this data should lead with the staples figure.
...

Sheet Dashboard
A2: Pick an item below to update the price trend and inflation charts. Scroll down for national inflation and state comparisons.

Sheet PIVOT_TABLE
F2: Price Trend by item | O2: MOM/YOY BY ITEMS
A3: Average Price | B3: Column Labels | M3: Column Labels
A4: Row Labels | B4: Apr-2025 | C4: Dec-2024 | D4: Feb-2025 | E4: Jan-2025 | F4: Mar-2025 | G4: Nov-2024 | H4: Grand Total | M4: Apr-2025 | O4: Dec-2024 | Q4: Feb-2025 | S4: Jan-2025 | U4: Mar-2025 | W4: Nov-2024 | Y4: Total Sum of MoM | Z4: Total Sum of YoY
A5: Agric hen eggs | B5: 259.31615 | C5: 252.1655 | D5: 251.94052 | E5: 248.04139 | F5: 261.18235 | G5: 247.2591 | H5: 1519.905 | L5: Row Labels | M5: Sum of MoM | N5: Sum of YoY | O5: Sum of MoM | P5: Sum of YoY | Q5: Sum of MoM | R5: Sum of YoY | S5: Sum of MoM | T5: Sum of YoY | U5: Sum of MoM | V5: Sum of YoY | W5: Sum of MoM | X5: Sum of YoY
A6: Agric hen eggs, (a Crate of 30 pieces) | B6: 6150.1781 | C6: 2866.9151 | D6: 5976.1159 | E6: 5878.1406 | F6: 7670.5592 | G6: 2833.973 | H6: 31375.882 | L6: Agric hen eggs | M6: -0.7145176 | N6: 71.904558 | O6: 1.9843144 | P6: 129.14896 | Q6: 1.5719659 | R6: 80.887516 | S6: -1.6354765 | T6: 113.07567 | U6: 3.6682586 | V6: 76.566018 | W6: 4.9159544 | X6: 124.57914 | Y6: 9.7904993 | Z6: 596.16186
A7: Beans Brown | B7: 2429.3886 | C7: 2501.3235 | D7: 2465.9628 | E7: 2458.5333 | F7: 2616.2636 | G7: 2720.9608 | H7: 15192.433 | L7: Agric hen eggs, (a Crate of 30 pieces) | M7: -19.820995 | O7: 1.162399 | P7: 128.45794 | Q7: 1.666772 | U7: 28.353589 | W7: 6.0776605 | X7: 135.7368 | Y7: 17.439426 | Z7: 264.19474
A8: Beans white | B8: 2097.3099 | C8: 2319.0422 | D8: 2114.3292 | E8: 2123.853 | F8: 2215.1071 | G8: 2546.7025 | H8: 13416.344 | L8: Beans Brown | M8: -7.1428215 | N8: 75.040225 | O8: -8.0720499 | P8: 187.28788 | Q8: 0.30219169 | R8: 109.34789 | S8: -1.7107038 | T8: 151.74825 | U8: 6.0950166 | V8: 111.9458 | W8: -2.7706082 | X8: 224.36831 | Y8: -13.298975 | Z8: 859.73836
A9: Beef Bone in | C9: 5153.1849 | G9: 5073.7358 | H9: 10226.921 | L9: Beans white | M9: -5.3178976 | N9: 59.675942 | O9: -8.9394163 | P9: 179.44916 | Q9: -0.44841891 | R9: 82.770467 | S9: -8.4168028 | T9: 130.50827 | U9: 4.7664205 | V9: 85.79749 | W9: -2.1747433 | X9: 218.14424 | Y9: -20.530858 | Z9: 756.34557
A10: Beef Boneless | B10: 6544.5369 | C10: 6150.1829 | D10: 6269.4588 | E10: 6122.5683 | F10: 6523.501 | G10: 6001.3163 | H10: 37611.564 | L10: Beef Bone in | O10: 1.5658889 | P10: 91.079587 | W10: 3.237562 | X10: 92.916594 | Y10: 4.8034509 | Z10: 183.99618
A11: Bread (sliced), 450g | B11: 1688.3998 | C11: 1610.8262 | D11: 1633.1854 | E11: 1604.7842 | F11: 1680.1747 | G11: 1588.0267 | H11: 9805.397 | L11: Beef Boneless | M11: 0.32246286 | N11: 38.901257 | O11: 2.4805654 | P11: 95.433786 | Q11: 2.3991652 | R11: 71.551615 | S11: -0.44900434 | T11: 84.649351 | U11: 4.052059 | V11: 51.386684 | W11: 2.4364204 | X11: 98.09587 | Y11: 11.241669 | Z11: 440.01856
A12: Bread (unsliced), 450g | B12: 1547.5179 | C12: 1512.1275 | D12: 1497.4272 | E12: 1452.983 | F12: 1561.2438 | G12: 1486.2466 | H12: 9057.546 | L12: Bread (sliced), 450g | M12: 0.48954126 | O12: 1.4357127 | P12: 88.390264 | Q12: 1.7697791 | U12: 2.8771572 | W12: 2.4372917 | X12: 94.962032 | Y12: 9.009482 | Z12: 183.3523
A13: Carrots, fresh | B13: 1931.3179 | D13: 1838.5928 | E13: 1787.1615 | F13: 1947.0497 | H13: 7504.1219 | L13: Bread (unsliced), 450g | M13: -0.87916515 | O13: 1.7413605 | P13: 85.512238 | Q13: 3.0588232 | U13: 4.2617539 | W13: 2.1871298 | X13: 86.754307 | Y13: 10.369902 | Z13: 172.26654
A14: Cat fresh fish | B14: 5572.4934 | C14: 4347.4446 | D14: 5284.3595 | E14: 5226.8706 | F14: 5507.1099 | G14: 4259.987 | H14: 30198.265 | L14: Carrots, fresh | M14: -0.80798556 | Q14: 2.8778248 | U14: 5.8989086 | Y14: 7.9687479
A15: Catfish :dried | C15: 6044.0788 | G15: 5787.7445 | H15: 11831.823 | L15: Cat fresh fish | M15: 1.1872558 | N15: 77.437818 | O15: 2.0530016 | P15: 85.20189 | Q15: 1.0998735 | R15: 91.574837 | S15: 20.228574 | T15: 109.29466 | U15: 4.2152771 | V15: 80.950399 | W15: 2.6814298 | X15: 90.925119 | Y15: 31.465411 | Z15: 535.38472
A16: Catfish Smoked | C16: 4475.0964 | G16: 4352.7683 | H16: 8827.8647 | L16: Catfish :dried | O16: 4.4289155 | P16: 80.016754 | W16: 3.8823436 | X16: 76.63717 | Y16: 8.311259 | Z16: 156.65392
A17: Chicken feet | B17: 3502.697 | C17: 3397.8334 | D17: 3346.6242 | E17: 3293.6296 | F17: 3487.0588 | G17: 3336.7032 | H17: 20364.546 | L17: Catfish Smoked | O17: 2.8103499 | P17: 55.95907 | W17: 2.6599243 | X17: 54.546335 | Y17: 5.4702742 | Z17: 110.50541
A18: Chicken meat (Frozen) | B18: 5740.1492 | C18: 6473.8064 | D18: 5552.7027 | E18: 5497.0311 | F18: 5675.6757 | G18: 6130.5146 | H18: 35069.88 | L18: Chicken feet | M18: 0.44846575 | N18: 31.635946 | O18: 1.8320509 | P18: 74.199754 | Q18: 1.6090049 | R18: 44.656477 | S18: -3.0667712 | T18: 60.500418 | U18: 4.1963045 | V18: 42.891521 | W18: 2.1140435 | X18: 86.293617 | Y18: 7.1330983 | Z18: 340.17773
A19: Chicken Wings | B19: 4771.9237 | C19: 4422.8022 | D19: 4394.4054 | E19: 4340.1078 | F19: 4671.3133 | G19: 4316.4129 | H19: 26916.965 | L19: Chicken meat (Frozen) | M19: 1.1359629 | N19: 18.865061 | O19: 5.5997228 | P19: 71.654927 | Q19: 1.012757 | R19: 27.041398 | S19: -15.088114 | T19: 37.165941 | U19: 2.2146508 | V19: 24.341673 | W19: 2.6547057 | X19: 68.148553 | Y19: -2.4703147 | Z19: 247.21755
A20: Cray fish small white | B20: 6655.6615 | D20: 6440.4411 | E20: 6227.0407 | F20: 6657.0025 | H20: 25980.146 | L20: Chicken Wings | M20: 2.1537917 | N20: 43.288042 | O20: 2.4647605 | P20: 95.278567 | Q20: 1.2510657 | R20: 59.685989 | S20: -1.8697281 | T20: 73.132752 | U20: 6.3013744 | V20: 56.107344 | W20: 2.9195945 | X20: 110.91658 | Y20: 13.220859 | Z20: 438.40927
A21: Dried Fish Sardine | C21: 4908.4226 | G21: 4766.5639 | H21: 9674.9865 | L21: Cray fish small white | M21: -0.0201443 | Q21: 3.4269948 | U21: 3.3625252 | Y21: 6.7693757
A22: Dried fish, Bonga | B22: 6657.7428 | D22: 6160.0213 | E22: 6131.9801 | F22: 6493.7843 | H22: 25443.529 | L22: Dried Fish Sardine | O22: 2.9761217 | P22: 71.38544 | W22: 2.6846165 | X22: 73.271968 | Y22: 5.6607383 | Z22: 144.65741
A23: Garri white | B23: 1345.0979 | C23: 1184.7662 | D23: 1277.2471 | E23: 1267.6349 | F23: 1362.9593 | G23: 1205.3886 | H23: 7643.0939 | L23: Dried fish, Bonga | M23: 2.5248521 | Q23: 0.45729427 | U23: 5.4182121 | Y23: 8.4003584
A24: Garri Yellow | B24: 1422.3398 | C24: 1296.9267 | D24: 1378.1547 | E24: 1358.9584 | F24: 1456.6513 | G24: 1311.0287 | H24: 8224.0597 | L24: Garri white | M24: -1.3104914 | N24: 57.910811 | O24: -1.7108511 | P24: 108.32161 | Q24: 0.75827745 | R24: 76.549718 | S24: 6.9945192 | T24: 111.03078 | U24: 6.710702 | V24: 81.753895 | W24: 0.61278118 | X24: 119.58037 | Y24: 12.054937 | Z24: 555.14718
A25: Ginger, fresh | B25: 4970.6588 | D25: 4371.8969 | E25: 4206.7995 | F25: 4600.2308 | H25: 18149.586 | L25: Garri Yellow | M25: -2.3554998 | N25: 56.341298 | O25: -1.0756402 | P25: 116.60552 | Q25: 1.4125736 | R25: 82.88488 | S25: 4.7829754 | T25: 117.7076 | U25: 5.6957726 | V25: 81.172867 | W25: 3.531011 | X25: 125.61466 | Y25: 11.991193 | Z25: 580.32682 | AD25: TOP 10 INFLATION RANKING
A26: Goat Meat Bone in | B26: 6708.4528 | D26: 6298.8934 | E26: 6202.3575 | F26: 6892.4623 | H26: 26102.166 | L26: Ginger, fresh | M26: 8.0523791 | Q26: 3.9245368 | U26: 5.2227643 | Y26: 17.19968 | AD26: Row Labels | AE26: Average of YoY | AH26: TOP 10 HIGHEST INFLATION RANKING
A27: Groundnut oil, 75cl | B27: 3250.3191 | C27: 3328.1693 | D27: 3039.8295 | E27: 2939.7346 | F27: 3218.8178 | G27: 3165.3812 | H27: 18942.252 | L27: Goat Meat Bone in | M27: -2.6697214 | Q27: 1.5564387 | U27: 9.4233838 | Y27: 8.310101 | AD27: Local Rice (Broken) | AE27: 157.51878 | AH27: Row Labels | AI27: Count of Highest Price | AO27: TOP 10 STATE WITH HIGHEST INFLATION RATE | AP27: TOP 10 STATE WITH HIGHEST INFLATION RATE
A28: Groundnuts, roasted,75cl bottle | B28: 2545.7164 | D28: 2392.4711 | E28: 2387.7568 | F28: 2487.6765 | H28: 9813.6208 | L28: Groundnut oil, 75cl | M28: 0.97866058 | O28: 5.1427648 | P28: 84.186821 | Q28: 3.4048939 | U28: 5.8881052 | W28: 8.0734425 | X28: 82.026853 | Y28: 23.487867 | Z28: 166.21367 | AD28: Beans Brown | AE28: 143.28973 | AH28: Enugu | AI28: 25 | AO28: Row Labels | AP28: Count of Lowest Price
A29: Iced Sardine | C29: 4014.2349 | G29: 3875.6589 | H29: 7889.8938 | L29: Groundnuts, roasted,75cl bottle | M29: 2.3330977 | Q29: 0.19743431 | U29: 3.9793781 | Y29: 6.5099101 | AD29: Plantain (unripe) | AE29: 133.72148 | AH29: Imo | AI29: 22 | AO29: Abuja | AP29: 10
A30: Irish Potatoe | B30: 1948.6077 | C30: 1818.2876 | D30: 1756.4073 | E30: 1790.9109 | F30: 1881.7563 | G30: 1778.9605 | H30: 10974.93 | L30: Iced Sardine | O30: 3.5755458 | P30: 74.231669 | W30: 4.5527696 | X30: 74.344787 | Y30: 8.1283154 | Z30: 148.57646 | AD30: Agric hen eggs, (a Crate of 30 pieces) | AE30: 132.09737 | AH30: Plateau | AI30: 19 | AO30: Osun | AP30: 10
A31: Local Rice (Broken) | B31: 2517.8856 | C31: 2512.3265 | D31: 2564.9518 | E31: 2508.155 | F31: 2671.729 | G31: 2485.1389 | H31: 15260.187 | L31: Irish Potatoe | M31: 3.5526087 | N31: 37.850556 | O31: 2.2106818 | P31: 80.679153 | Q31: -1.9265956 | R31: 55.347702 | S31: -1.505634 | T31: 70.276157 | U31: 7.136671 | V31: 50.006412 | W31: 2.6237522 | X31: 103.86148 | Y31: 12.091484 | Z31: 398.02146 | AD31: Beans white | AE31: 126.05759 | AH31: Ebonyi | AI31: 19 | AO31: Kebbi | AP31: 11
A32: Mackerel, Frozen | B32: 5417.3963 | C32: 4287.654 | D32: 5233.1514 | E32: 5117.8059 | F32: 5482.6328 | G32: 4203.7598 | H32: 29742.4 | L32: Local Rice (Broken) | M32: -5.7581946 | O32: 1.0940094 | P32: 150.706 | Q32: 2.2644877 | U32: 4.1629298 | W32: 2.3260488 | X32: 164.33156 | Y32: 4.0892809 | Z32: 315.03756 | AD32: Rice Medium Grained | AE32: 117.94772 | AH32: Gombe | AI32: 15 | AO32: Kogi | AP32: 13
A33: Maize (Corn) Grains (White) sold loose | B33: 1239.6097 | C33: 1151.1347 | D33: 1169.321 | E33: 1168.338 | F33: 1278.7595 | G33: 1156.9086 | H33: 7164.0715 | L33: Mackerel, Frozen | M33: -1.1898743 | N33: 67.982055 | O33: 1.9956959 | P33: 89.201112 | Q33: 2.2538078 | R33: 92.978981 | S33: 19.361448 | T33: 108.21326 | U33: 4.7673251 | V33: 84.469122 | W33: 1.6347896 | X33: 90.64289 | Y33: 28.823192 | Z33: 533.48742 | AD33: Plantain (ripe) | AE33: 116.2034 | AH33: Ogun | AI33: 14 | AO33: Niger | AP33: 13
A34: Maize grain yellow sold loose | C34: 1160.2151 | G34: 1163.2443 | H34: 2323.4595 | L34: Maize (Corn) Grains (White) sold loose | M34: -3.0615498 | N34: 55.41565 | O34: -0.49908219 | P34: 99.237028 | Q34: 0.084139931 | R34: 60.301365 | S34: 1.494461 | T34: 84.306004 | U34: 9.3591501 | V34: 68.733508 | W34: 7.0773375 | X34: 107.58071 | Y34: 14.454457 | Z34: 475.57426 | AD34: Rice agric sold loose | AE34: 116.1475 | AH34: Akwa Ibom | AI34: 11 | AO34: Borno | AP34: 15
A35: Mudfish (aro) fresh | C35: 4166.6761 | G35: 4136.4787 | H35: 8303.1548 | L35: Maize grain yellow sold loose | O35: -0.26040698 | P35: 96.728586 | W35: 7.6166339 | X35: 108.02618 | Y35: 7.3562269 | Z35: 204.75477 | AD35: Yam Tuber | AE35: 114.98585 | AH35: Kwara | AI35: 11 | AO35: Benue | AP35: 16
A36: Mudfish : dried | C36: 5632.3371 | G36: 5345.9909 | H36: 10978.328 | L36: Mudfish (aro) fresh | O36: 0.73002725 | P36: 88.147628 | W36: 2.026348 | X36: 94.108678 | Y36: 2.7563752 | Z36: 182.25631 | AD36: Tilapia fresh fish (Epiya) | AE36: 105.83782 | AH36: Kogi | AI36: 10 | AO36: Taraba | AP36: 17
A37: Onions, fresh | B37: 1503.5645 | C37: 2057.8109 | D37: 1372.0419 | E37: 1367.6216 | F37: 1434.8498 | G37: 1878.0015 | H37: 9613.8902 | L37: Mudfish : dried | O37: 5.3562791 | P37: 79.516485 | W37: 4.009383 | X37: 79.233988 | Y37: 9.365662 | Z37: 158.75047 | AD37: Maize grain yellow sold loose | AE37: 102.37738 | AH37: Ekiti | AI37: 10 | AO37: Oyo | AP37: 18
A38: Palm oil, 75cl | B38: 2516.3572 | C38: 2582.348 | D38: 2384.1511 | E38: 2329.5428 | F38: 2511.7729 | G38: 2466.7871 | H38: 14790.959 | L38: Onions, fresh | M38: 4.7889796 | N38: 47.577102 | O38: 9.5745057 | P38: 111.73946 | Q38: 0.32321366 | R38: 49.850061 | S38: -33.539978 | T38: 55.200318 | U38: 4.5776972 | V38: 52.827851 | W38: 50.057212 | X38: 174.65061 | Y38: 35.78163 | Z38: 491.8454 | AD38: Agric hen eggs | AE38: 99.36031 | AH38: Grand Total | AI38: 156 | AO38: Adamawa | AP38: 21
A39: Plantain (ripe) | B39: 2057.3966 | C39: 1533.681 | D39: 1914.499 | E39: 1876.0259 | F39: 2002.5842 | G39: 1540.0464 | H39: 10924.233 | L39: Palm oil, 75cl | M39: 0.18251061 | N39: 53.994735 | O39: 4.684671 | P39: 81.17625 | Q39: 2.3441642 | R39: 52.687358 | S39: -9.7897415 | T39: 59.91669 | U39: 5.3529241 | V39: 60.404329 | W39: 14.895274 | X39: 80.036482 | Y39: 17.669802 | Z39: 388.21584 | AD39: Garri Yellow | AE39: 96.721137 | AO39: Yobe | AP39: 29
A40: Plantain (unripe) | B40: 2231.8083 | C40: 1550.1514 | D40: 2127.6713 | E40: 2119.0689 | F40: 2214.5653 | G40: 1566.2043 | H40: 11809.469 | L40: Plantain (ripe) | M40: 2.7370858 | N40: 103.89396 | O40: -0.41332773 | P40: 102.33499 | Q40: 2.0507792 | R40: 126.16629 | S40: 22.32178 | T40: 131.41758 | U40: 4.6009508 | V40: 111.38821 | W40: 2.1788988 | X40: 122.01937 | Y40: 33.476167 | Z40: 697.22039 | AD40: Garri white | AE40: 92.52453 | AO40: Grand Total | AP40: 173
A41: Rice agric sold loose | C41: 2037.3032 | G41: 2042.3537 | H41: 4079.6569 | L41: Plantain (unripe) | M41: 0.77861702 | N41: 123.08987 | O41: -1.0249546 | P41: 107.78524 | Q41: 0.405949 | R41: 147.69398 | S41: 36.700773 | T41: 160.9867 | U41: 4.0839961 | V41: 137.31969 | W41: 1.7242721 | X41: 125.45341 | Y41: 42.668653 | Z41: 802.3289 | AD41: Beef Bone in | AE41: 91.99809
...

Sheet Standardized Data
A1: Month | B1: Standardized Item | C1: Item Label | D1: Match Confidence | E1: Avg (Same Month Last Year) | F1: Avg (Previous Month) | G1: Avg (Current Month) | H1: MoM | I1: YoY | J1: Highest | K1: Highest State | L1: Highest Price | M1: Lowest | N1: Lowest State | O1: Lowest Price | P1: Source File
A2: Nov-2024 | B2: Agric hen eggs | C2: Agric eggs(medium size price of one) | D2: Confirmed | E2: 110.09887 | F2: 235.6735 | G2: 247.2591 | H2: 4.9159544 | I2: 124.57914 | J2: Gombe (300) | K2: Gombe | L2: 300 | M2: Borno (199.73) | N2: Borno | O2: 199.73 | P2: selected_food_Nov_2024.xlsx
A3: Dec-2024 | B3: Agric hen eggs | C3: Agric eggs(medium size price of one) | D3: Confirmed | E3: 110.04436 | F3: 247.2591 | G3: 252.1655 | H3: 1.9843144 | I3: 129.14896 | J3: Bauchi (300.73) | K3: Bauchi | L3: 300.73 | M3: Taraba (212) | N3: Taraba | O3: 212 | P3: selected_food_Dec_2024.xlsx
A4: Jan-2025 | B4: Agric hen eggs | C4: Agric hen eggs | D4: Confirmed | E4: 116.41 | F4: 252.1655 | G4: 248.04139 | H4: -1.6354765 | I4: 113.07567 | J4: Enugu (325) | K4: Enugu | L4: 325 | M4: Adamawa (200) | N4: Adamawa | O4: 200 | P4: Selected_food_table_Jan25.xlsx
A5: Feb-2025 | B5: Agric hen eggs | C5: Agric hen eggs, | D5: Confirmed | E5: 139.28021 | F5: 248.04139 | G5: 251.94052 | H5: 1.5719659 | I5: 80.887516 | J5: Enugu (325) | K5: Enugu | L5: 325 | M5: Adamawa (200) | N5: Adamawa | O5: 200 | P5: selected_food_table_Feb_25.xlsx
A6: Mar-2025 | B6: Agric hen eggs | C6: Agric hen eggs, | D6: Confirmed | E6: 147.92334 | F6: 251.94052 | G6: 261.18235 | H6: 3.6682586 | I6: 76.566018 | J6: Enugu (354.75) | K6: Enugu | L6: 354.75 | M6: Kaduna (210) | N6: Kaduna | O6: 210 | P6: selected_food_table_Mar_25.xlsx
A7: Apr-2025 | B7: Agric hen eggs | C7: Agric hen eggs, | D7: Confirmed | E7: 150.84891 | F7: 261.18235 | G7: 259.31615 | H7: -0.7145176 | I7: 71.904558 | J7: Enugu (356.73) | K7: Enugu | L7: 356.73 | M7: Kaduna (220) | N7: Kaduna | O7: 220 | P7: selected_food_table_Apr25.xlsx
A8: Nov-2024 | B8: Agric hen eggs, (a Crate of 30 pieces) | C8: Agric eggs medium size | D8: Likely | E8: 1202.1768 | F8: 2671.6021 | G8: 2833.973 | H8: 6.0776605 | I8: 135.7368 | J8: Gombe (3600) | K8: Gombe | L8: 3600 | M8: Borno (2381.15) | N8: Borno | O8: 2381.15 | P8: selected_food_Nov_2024.xlsx
A9: Dec-2024 | B9: Agric hen eggs, (a Crate of 30 pieces) | C9: Agric eggs medium size | D9: Likely | E9: 1254.8984 | F9: 2833.973 | G9: 2866.9151 | H9: 1.162399 | I9: 128.45794 | J9: Gombe (3600.65) | K9: Gombe | L9: 3600.65 | M9: Borno (2431.2) | N9: Borno | O9: 2431.2 | P9: selected_food_Dec_2024.xlsx
A10: Jan-2025 | B10: Agric hen eggs, (a Crate of 30 pieces) | C10: Agric hen eggs, (a Crate of 30 pieces) | D10: Likely | G10: 5878.1406 | J10: Enugu (7000) | K10: Enugu | L10: 7000 | M10: Niger (4613.06) | N10: Niger | O10: 4613.06 | P10: Selected_food_table_Jan25.xlsx
A11: Feb-2025 | B11: Agric hen eggs, (a Crate of 30 pieces) | C11: Agric hen eggs, (a Crate of 30 pieces) | D11: Likely | F11: 5878.1406 | G11: 5976.1159 | H11: 1.666772 | J11: Enugu (7250) | K11: Enugu | L11: 7250 | M11: Kogi (5000) | N11: Kogi | O11: 5000 | P11: selected_food_table_Feb_25.xlsx
A12: Mar-2025 | B12: Agric hen eggs, (a Crate of 30 pieces) | C12: Agric hen eggs, (a Crate of 30 pieces) | D12: Likely | F12: 5976.1159 | G12: 7670.5592 | H12: 28.353589 | J12: Enugu (7930) | K12: Enugu | L12: 7930 | M12: Niger (5300) | N12: Niger | O12: 5300 | P12: selected_food_table_Mar_25.xlsx
A13: Apr-2025 | B13: Agric hen eggs, (a Crate of 30 pieces) | C13: Agric hen eggs, (a Crate of 30 pieces) | D13: Likely | F13: 7670.5592 | G13: 6150.1781 | H13: -19.820995 | J13: Enugu (7869.33) | K13: Enugu | L13: 7869.33 | M13: Jigawa (540) | N13: Jigawa | O13: 540 | P13: selected_food_table_Apr25.xlsx
A14: Nov-2024 | B14: Beans Brown | C14: Beans brown,sold loose | D14: Confirmed | E14: 838.84915 | F14: 2798.4962 | G14: 2720.9608 | H14: -2.7706082 | I14: 224.36831 | J14: Bauchi (3675) | K14: Bauchi | L14: 3675 | M14: Adamawa (1925) | N14: Adamawa | O14: 1925 | P14: selected_food_Nov_2024.xlsx
A15: Dec-2024 | B15: Beans Brown | C15: Beans brown,sold loose | D15: Confirmed | E15: 870.66795 | F15: 2720.9608 | G15: 2501.3235 | H15: -8.0720499 | I15: 187.28788 | J15: Bauchi (3500.32) | K15: Bauchi | L15: 3500.32 | M15: Yobe (1755.63) | N15: Yobe | O15: 1755.63 | P15: selected_food_Dec_2024.xlsx
A16: Jan-2025 | B16: Beans Brown | C16: Beans Brown | D16: Confirmed | E16: 976.58407 | F16: 2501.3235 | G16: 2458.5333 | H16: -1.7107038 | I16: 151.74825 | J16: Abia (3230.87) | K16: Abia | L16: 3230.87 | M16: Sokoto (1575.36) | N16: Sokoto | O16: 1575.36 | P16: Selected_food_table_Jan25.xlsx
A17: Feb-2025 | B17: Beans Brown | C17: Beans Brown | D17: Confirmed | E17: 1177.9258 | F17: 2458.5333 | G17: 2465.9628 | H17: 0.30219169 | I17: 109.34789 | J17: Ebonyi (3200) | K17: Ebonyi | L17: 3200 | M17: Sokoto (1572.83) | N17: Sokoto | O17: 1572.83 | P17: selected_food_table_Feb_25.xlsx
A18: Mar-2025 | B18: Beans Brown | C18: Beans Brown | D18: Confirmed | E18: 1234.4022 | F18: 2465.9628 | G18: 2616.2636 | H18: 6.0950166 | I18: 111.9458 | J18: Abia (3651.13) | K18: Abia | L18: 3651.13 | M18: Sokoto (1634.36) | N18: Sokoto | O18: 1634.36 | P18: selected_food_table_Mar_25.xlsx
A19: Apr-2025 | B19: Beans Brown | C19: Beans Brown | D19: Confirmed | E19: 1387.903 | F19: 2616.2636 | G19: 2429.3886 | H19: -7.1428215 | I19: 75.040225 | J19: Abia (3600) | K19: Abia | L19: 3600 | M19: Sokoto (1658.02) | N19: Sokoto | O19: 1658.02 | P19: selected_food_table_Apr25.xlsx
A20: Nov-2024 | B20: Beans white | C20: Beans:white black eye. sold loose | D20: Confirmed | E20: 800.48677 | F20: 2603.318 | G20: 2546.7025 | H20: -2.1747433 | I20: 218.14424 | J20: Ebonyi (3157.2) | K20: Ebonyi | L20: 3157.2 | M20: Adamawa (1750) | N20: Adamawa | O20: 1750 | P20: selected_food_Nov_2024.xlsx
A21: Dec-2024 | B21: Beans white | C21: Beans:white black eye. sold loose | D21: Confirmed | E21: 829.86193 | F21: 2546.7025 | G21: 2319.0422 | H21: -8.9394163 | I21: 179.44916 | J21: Abuja (3176.63) | K21: Abuja | L21: 3176.63 | M21: Yobe (1534.59) | N21: Yobe | O21: 1534.59 | P21: selected_food_Dec_2024.xlsx
A22: Jan-2025 | B22: Beans white | C22: Beans white | D22: Confirmed | E22: 921.37822 | F22: 2319.0422 | G22: 2123.853 | H22: -8.4168028 | I22: 130.50827 | J22: Enugu (2722.76) | K22: Enugu | L22: 2722.76 | M22: Sokoto (1370.59) | N22: Sokoto | O22: 1370.59 | P22: Selected_food_table_Jan25.xlsx
A23: Feb-2025 | B23: Beans white | C23: Beans white | D23: Confirmed | E23: 1156.8221 | F23: 2123.853 | G23: 2114.3292 | H23: -0.44841891 | I23: 82.770467 | J23: Abia (2825.33) | K23: Abia | L23: 2825.33 | M23: Yobe (1371.48) | N23: Yobe | O23: 1371.48 | P23: selected_food_table_Feb_25.xlsx
A24: Mar-2025 | B24: Beans white | C24: Beans white | D24: Confirmed | E24: 1192.2158 | F24: 2114.3292 | G24: 2215.1071 | H24: 4.7664205 | I24: 85.79749 | J24: Enugu (3122.19) | K24: Enugu | L24: 3122.19 | M24: Abuja (1521.57) | N24: Abuja | O24: 1521.57 | P24: selected_food_table_Mar_25.xlsx
A25: Apr-2025 | B25: Beans white | C25: Beans white | D25: Confirmed | E25: 1313.479 | F25: 2215.1071 | G25: 2097.3099 | H25: -5.3178976 | I25: 59.675942 | J25: Enugu (3100) | K25: Enugu | L25: 3100 | M25: Kaduna (1503.96) | N25: Kaduna | O25: 1503.96 | P25: selected_food_table_Apr25.xlsx
... A35: Dec-2024 | B35: Bread (sliced), 450g | C35: Bread sliced 500g | D35: Likely | E35: 855.04746 | F35: 1588.0267 | G35: 1610.8262 | H35: 1.4357127 | I35: 88.390264 | J35: Akwa Ibom (1890) | K35: Akwa Ibom | L35: 1890 | M35: Benue (1299.01) | N35: Benue | O35: 1299.01 | P35: selected_food_Dec_2024.xlsx
A36: Jan-2025 | B36: Bread (sliced), 450g | C36: Bread (sliced), 450g | D36: Likely | G36: 1604.7842 | J36: Ogun (1950) | K36: Ogun | L36: 1950 | M36: Osun (1300) | N36: Osun | O36: 1300 | P36: Selected_food_table_Jan25.xlsx
A37: Feb-2025 | B37: Bread (sliced), 450g | C37: Bread (sliced), 450g | D37: Likely | F37: 1604.7842 | G37: 1633.1854 | H37: 1.7697791 | J37: Ogun (1950) | K37: Ogun | L37: 1950 | M37: Osun (1256.25) | N37: Osun | O37: 1256.25 | P37: selected_food_table_Feb_25.xlsx
A38: Mar-2025 | B38: Bread (sliced), 450g | C38: Bread (sliced), 450g | D38: Likely | F38: 1633.1854 | G38: 1680.1747 | H38: 2.8771572 | J38: Ogun (2187.92) | K38: Ogun | L38: 2187.92 | M38: Osun (1256.25) | N38: Osun | O38: 1256.25 | P38: selected_food_table_Mar_25.xlsx
A39: Apr-2025 | B39: Bread (sliced), 450g | C39: Bread (sliced), 450g | D39: Likely | F39: 1680.1747 | G39: 1688.3998 | H39: 0.48954126 | J39: Ogun (2187.92) | K39: Ogun | L39: 2187.92 | M39: Osun (1256.25) | N39: Osun | O39: 1256.25 | P39: selected_food_table_Apr25.xlsx
A40: Nov-2024 | B40: Bread (unsliced), 450g | C40: Bread unsliced 500g | D40: Likely | E40: 795.82989 | F40: 1454.4362 | G40: 1486.2466 | H40: 2.1871298 | I40: 86.754307 | J40: Delta (1805.42) | K40: Delta | L40: 1805.42 | M40: Borno (1053.56) | N40: Borno | O40: 1053.56 | P40: selected_food_Nov_2024.xlsx
A41: Dec-2024 | B41: Bread (unsliced), 450g | C41: Bread unsliced 500g | D41: Likely | E41: 815.10931 | F41: 1486.2466 | G41: 1512.1275 | H41: 1.7413605 | I41: 85.512238 | J41: Delta (1823.75) | K41: Delta | L41: 1823.75 | M41: Yobe (1112.87) | N41: Yobe | O41: 1112.87 | P41: selected_food_Dec_2024.xlsx
A42: Jan-2025 | B42: Bread (unsliced), 450g | C42: Bread (unsliced), 450g | D42: Likely | G42: 1452.983 | J42: Akwa Ibom (1800) | K42: Akwa Ibom | L42: 1800 | M42: Yobe (900) | N42: Yobe | O42: 900 | P42: Selected_food_table_Jan25.xlsx
A43: Feb-2025 | B43: Bread (unsliced), 450g | C43: Bread (unsliced), 450g | D43: Likely | F43: 1452.983 | G43: 1497.4272 | H43: 3.0588232 | J43: Akwa Ibom (1900) | K43: Akwa Ibom | L43: 1900 | M43: Yobe (900) | N43: Yobe | O43: 900 | P43: selected_food_table_Feb_25.xlsx
A44: Mar-2025 | B44: Bread (unsliced), 450g | C44: Bread (unsliced), 450g | D44: Likely | F44: 1497.4272 | G44: 1561.2438 | H44: 4.2617539 | J44: Ebonyi (1908.56) | K44: Ebonyi | L44: 1908.56 | M44: Yobe (960) | N44: Yobe | O44: 960 | P44: selected_food_table_Mar_25.xlsx
A45: Apr-2025 | B45: Bread (unsliced), 450g | C45: Bread (unsliced), 450g | D45: Likely | F45: 1561.2438 | G45: 1547.5179 | H45: -0.87916515 | J45: Ebonyi (1922.3) | K45: Ebonyi | L45: 1922.3 | M45: Ekiti (1000) | N45: Ekiti | O45: 1000 | P45: selected_food_table_Apr25.xlsx
A46: Jan-2025 | B46: Carrots, fresh | C46: Carrots, fresh | D46: New (2025) | G46: 1787.1615 | J46: Bayelsa (2572.73) | K46: Bayelsa | L46: 2572.73 | M46: Benue (1400) | N46: Benue | O46: 1400 | P46: Selected_food_table_Jan25.xlsx
A47: Feb-2025 | B47: Carrots, fresh | C47: Carrots, fresh | D47: New (2025) | F47: 1787.1615 | G47: 1838.5928 | H47: 2.8778248 | J47: Imo (2557.14) | K47: Imo | L47: 2557.14 | M47: Zamfara (1410) | N47: Zamfara | O47: 1410 | P47: selected_food_table_Feb_25.xlsx
A48: Mar-2025 | B48: Carrots, fresh | C48: Carrots, fresh | D48: New (2025) | F48: 1838.5928 | G48: 1947.0497 | H48: 5.8989086 | J48: Imo (2980.7) | K48: Imo | L48: 2980.7 | M48: Zamfara (1450) | N48: Zamfara | O48: 1450 | P48: selected_food_table_Mar_25.xlsx
A49: Apr-2025 | B49: Carrots, fresh | C49: Carrots, fresh | D49: New (2025) | F49: 1947.0497 | G49: 1931.3179 | H49: -0.80798556 | J49: Imo (3000) | K49: Imo | L49: 3000 | M49: Borno (1200) | N49: Borno | O49: 1200 | P49: selected_food_table_Apr25.xlsx
...

Sheet Item Summary
A1: Standardized Item | B1: Match Confidence | C1: Months Covered | D1: Avg Price Nov-2024 | E1: Avg Price Dec-2024 | F1: Avg Price Jan-2025 | G1: Avg Price Feb-2025 | H1: Avg Price Mar-2025 | I1: Avg Price Apr-2025 | J1: Avg MoM % | K1: Avg YoY % | L1: Latest Price
A2: Agric hen eggs | B2: =IFERROR(INDEX('Standardized Data'!$D$2:$D$255,MATCH($A2,'Standardized Data'!$B$2:$B$255,0)),"") -> Confirmed | C2: =COUNTIF('Standardized Data'!$B$2:$B$255,$A2) -> 6 | D2: =IF(SUMIFS('Standardized Data'!$G$2:$G$255,'Standardized Data'!$B$2:$B$255,$A2,'Standardized Data'!$A$2:$A$255,"Nov-2024")=0,"",SUMIFS('Standardized Data'!$G$2:$G$255,'Standardized Data'!$B$2:$B$255,$A2,'Standardized Data'!$A$2:$A$255,"Nov-2024")) -> 247.2591 | E2: =IF(SUMIFS('Standardized Data'!$G$2:$G$255,'Standardized Data'!$B$2:$B$255,$A2,'Standardized Data'!$A$2:$A$255,"Dec-2024")=0,"",SUMIFS('Standardized Data'!$G$2:$G$255,'Standardized Data'!$B$2:$B$255,$A2,'Standardized Data'!$A$2:$A$255,"Dec-2024")) -> 252.1655 | F2: =IF(SUMIFS('Standardized Data'!$G$2:$G$255,'Standardized Data'!$B$2:$B$255,$A2,'Standardized Data'!$A$2:$A$255,"Jan-2025")=0,"",SUMIFS('Standardized Data'!$G$2:$G$255,'Standardized Data'!$B$2:$B$255,$A2,'Standardized Data'!$A$2:$A$255,"Jan-2025")) -> 248.04139 | G2: =IF(SUMIFS('Standardized Data'!$G$2:$G$255,'Standardized Data'!$B$2:$B$255,$A2,'Standardized Data'!$A$2:$A$255,"Feb-2025")=0,"",SUMIFS('Standardized Data'!$G$2:$G$255,'Standardized Data'!$B$2:$B$255,$A2,'Standardized Data'!$A$2:$A$255,"Feb-2025")) -> 251.94052 | H2: =IF(SUMIFS('Standardized Data'!$G$2:$G$255,'Standardized Data'!$B$2:$B$255,$A2,'Standardized Data'!$A$2:$A$255,"Mar-2025")=0,"",SUMIFS('Standardized Data'!$G$2:$G$255,'Standardized Data'!$B$2:$B$255,$A2,'Standardized Data'!$A$2:$A$255,"Mar-2025")) -> 261.18235 | I2: =IF(SUMIFS('Standardized Data'!$G$2:$G$255,'Standardized Data'!$B$2:$B$255,$A2,'Standardized Data'!$A$2:$A$255,"Apr-2025")=0,"",SUMIFS('Standardized Data'!$G$2:$G$255,'Standardized Data'!$B$2:$B$255,$A2,'Standardized Data'!$A$2:$A$255,"Apr-2025")) -> 259.31615 | J2: =IFERROR(AVERAGEIFS('Standardized Data'!$H$2:$H$255,'Standardized Data'!$B$2:$B$255,$A2),"") -> 1.6317499 | K2: =IFERROR(AVERAGEIFS('Standardized Data'!$I$2:$I$255,'Standardized Data'!$B$2:$B$255,$A2),"") -> 99.36031 | L2: =IF(I2<>"",I2,IF(H2<>"",H2,IF(G2<>"",G2,IF(F2<>"",F2,IF(E2<>"",E2,IF(D2<>"",D2,"")))))) -> 259.31615
A3: Agric hen eggs, (a Crate of 30 pieces) | B3: =IFERROR(INDEX('Standardized Data'!$D$2:$D$255,MATCH($A3,'Standardized Data'!$B$2:$B$255,0)),"") -> Likely | C3: =COUNTIF('Standardized Data'!$B$2:$B$255,$A3) -> 6 | D3: =IF(SUMIFS('Standardized Data'!$G$2:$G$255,'Standardized Data'!$B$2:$B$255,$A3,'Standardized Data'!$A$2:$A$255,"Nov-2024")=0,"",SUMIFS('Standardized Data'!$G$2:$G$255,'Standardized Data'!$B$2:$B$255,$A3,'Standardized Data'!$A$2:$A$255,"Nov-2024")) -> 2833.973 | E3: =IF(SUMIFS('Standardized Data'!$G$2:$G$255,'Standardized Data'!$B$2:$B$255,$A3,'Standardized Data'!$A$2:$A$255,"Dec-2024")=0,"",SUMIFS('Standardized Data'!$G$2:$G$255,'Standardized Data'!$B$2:$B$255,$A3,'Standardized Data'!$A$2:$A$255,"Dec-2024")) -> 2866.9151 | F3: =IF(SUMIFS('Standardized Data'!$G$2:$G$255,'Standardized Data'!$B$2:$B$255,$A3,'Standardized Data'!$A$2:$A$255,"Jan-2025")=0,"",SUMIFS('Standardized Data'!$G$2:$G$255,'Standardized Data'!$B$2:$B$255,$A3,'Standardized Data'!$A$2:$A$255,"Jan-2025")) -> 5878.1406 | G3: =IF(SUMIFS('Standardized Data'!$G$2:$G$255,'Standardized Data'!$B$2:$B$255,$A3,'Standardized Data'!$A$2:$A$255,"Feb-2025")=0,"",SUMIFS('Standardized Data'!$G$2:$G$255,'Standardized Data'!$B$2:$B$255,$A3,'Standardized Data'!$A$2:$A$255,"Feb-2025")) -> 5976.1159 | H3: =IF(SUMIFS('Standardized Data'!$G$2:$G$255,'Standardized Data'!$B$2:$B$255,$A3,'Standardized Data'!$A$2:$A$255,"Mar-2025")=0,"",SUMIFS('Standardized Data'!$G$2:$G$255,'Standardized Data'!$B$2:$B$255,$A3,'Standardized Data'!$A$2:$A$255,"Mar-2025")) -> 7670.5592 | I3: =IF(SUMIFS('Standardized Data'!$G$2:$G$255,'Standardized Data'!$B$2:$B$255,$A3,'Standardized Data'!$A$2:$A$255,"Apr-2025")=0,"",SUMIFS('Standardized Data'!$G$2:$G$255,'Standardized Data'!$B$2:$B$255,$A3,'Standardized Data'!$A$2:$A$255,"Apr-2025")) -> 6150.1781 | J3: =IFERROR(AVERAGEIFS('Standardized Data'!$H$2:$H$255,'Standardized Data'!$B$2:$B$255,$A3),"") -> 3.4878852 | K3: =IFERROR(AVERAGEIFS('Standardized Data'!$I$2:$I$255,'Standardized Data'!$B$2:$B$255,$A3),"") -> 132.09737 | L3: =IF(I3<>"",I3,IF(H3<>"",H3,IF(G3<>"",G3,IF(F3<>"",F3,IF(E3<>"",E3,IF(D3<>"",D3,"")))))) -> 6150.1781
A4: Beans Brown | B4: =IFERROR(INDEX('Standardized Data'!$D$2:$D$255,MATCH($A4,'Standardized Data'!$B$2:$B$255,0)),"") -> Confirmed | C4: =COUNTIF('Standardized Data'!$B$2:$B$255,$A4) -> 6 | D4: =IF(SUMIFS('Standardized Data'!$G$2:$G$255,'Standardized Data'!$B$2:$B$255,$A4,'Standardized Data'!$A$2:$A$255,"Nov-2024")=0,"",SUMIFS('Standardized Data'!$G$2:$G$255,'Standardized Data'!$B$2:$B$255,$A4,'Standardized Data'!$A$2:$A$255,"Nov-2024")) -> 2720.9608 | E4: =IF(SUMIFS('Standardized Data'!$G$2:$G$255,'Standardized Data'!$B$2:$B$255,$A4,'Standardized Data'!$A$2:$A$255,"Dec-2024")=0,"",SUMIFS('Standardized Data'!$G$2:$G$255,'Standardized Data'!$B$2:$B$255,$A4,'Standardized Data'!$A$2:$A$255,"Dec-2024")) -> 2501.3235 | F4: =IF(SUMIFS('Standardized Data'!$G$2:$G$255,'Standardized Data'!$B$2:$B$255,$A4,'Standardized Data'!$A$2:$A$255,"Jan-2025")=0,"",SUMIFS('Standardized Data'!$G$2:$G$255,'Standardized Data'!$B$2:$B$255,$A4,'Standardized Data'!$A$2:$A$255,"Jan-2025")) -> 2458.5333 | G4: =IF(SUMIFS('Standardized Data'!$G$2:$G$255,'Standardized Data'!$B$2:$B$255,$A4,'Standardized Data'!$A$2:$A$255,"Feb-2025")=0,"",SUMIFS('Standardized Data'!$G$2:$G$255,'Standardized Data'!$B$2:$B$255,$A4,'Standardized Data'!$A$2:$A$255,"Feb-2025")) -> 2465.9628 | H4: =IF(SUMIFS('Standardized Data'!$G$2:$G$255,'Standardized Data'!$B$2:$B$255,$A4,'Standardized Data'!$A$2:$A$255,"Mar-2025")=0,"",SUMIFS('Standardized Data'!$G$2:$G$255,'Standardized Data'!$B$2:$B$255,$A4,'Standardized Data'!$A$2:$A$255,"Mar-2025")) -> 2616.2636 | I4: =IF(SUMIFS('Standardized Data'!$G$2:$G$255,'Standardized Data'!$B$2:$B$255,$A4,'Standardized Data'!$A$2:$A$255,"Apr-2025")=0,"",SUMIFS('Standardized Data'!$G$2:$G$255,'Standardized Data'!$B$2:$B$255,$A4,'Standardized Data'!$A$2:$A$255,"Apr-2025")) -> 2429.3886 | J4: =IFERROR(AVERAGEIFS('Standardized Data'!$H$2:$H$255,'Standardized Data'!$B$2:$B$255,$A4),"") -> -2.2164959 | K4: =IFERROR(AVERAGEIFS('Standardized Data'!$I$2:$I$255,'Standardized Data'!$B$2:$B$255,$A4),"") -> 143.28973 | L4: =IF(I4<>"",I4,IF(H4<>"",H4,IF(G4<>"",G4,IF(F4<>"",F4,IF(E4<>"",E4,IF(D4<>"",D4,"")))))) -> 2429.3886
A5: Beans white | B5: =IFERROR(INDEX('Standardized Data'!$D$2:$D$255,MATCH($A5,'Standardized Data'!$B$2:$B$255,0)),"") -> Confirmed | C5: =COUNTIF('Standardized Data'!$B$2:$B$255,$A5) -> 6 | D5: =IF(SUMIFS('Standardized Data'!$G$2:$G$255,'Standardized Data'!$B$2:$B$255,$A5,'Standardized Data'!$A$2:$A$255,"Nov-2024")=0,"",SUMIFS('Standardized Data'!$G$2:$G$255,'Standardized Data'!$B$2:$B$255,$A5,'Standardized Data'!$A$2:$A$255,"Nov-2024")) -> 2546.7025 | E5: =IF(SUMIFS('Standardized Data'!$G$2:$G$255,'Standardized Data'!$B$2:$B$255,$A5,'Standardized Data'!$A$2:$A$255,"Dec-2024")=0,"",SUMIFS('Standardized Data'!$G$2:$G$255,'Standardized Data'!$B$2:$B$255,$A5,'Standardized Data'!$A$2:$A$255,"Dec-2024")) -> 2319.0422 | F5: =IF(SUMIFS('Standardized Data'!$G$2:$G$255,'Standardized Data'!$B$2:$B$255,$A5,'Standardized Data'!$A$2:$A$255,"Jan-2025")=0,"",SUMIFS('Standardized Data'!$G$2:$G$255,'Standardized Data'!$B$2:$B$255,$A5,'Standardized Data'!$A$2:$A$255,"Jan-2025")) -> 2123.853 | G5: =IF(SUMIFS('Standardized Data'!$G$2:$G$255,'Standardized Data'!$B$2:$B$255,$A5,'Standardized Data'!$A$2:$A$255,"Feb-2025")=0,"",SUMIFS('Standardized Data'!$G$2:$G$255,'Standardized Data'!$B$2:$B$255,$A5,'Standardized Data'!$A$2:$A$255,"Feb-2025")) -> 2114.3292 | H5: =IF(SUMIFS('Standardized Data'!$G$2:$G$255,'Standardized Data'!$B$2:$B$255,$A5,'Standardized Data'!$A$2:$A$255,"Mar-2025")=0,"",SUMIFS('Standardized Data'!$G$2:$G$255,'Standardized Data'!$B$2:$B$255,$A5,'Standardized Data'!$A$2:$A$255,"Mar-2025")) -> 2215.1071 | I5: =IF(SUMIFS('Standardized Data'!$G$2:$G$255,'Standardized Data'!$B$2:$B$255,$A5,'Standardized Data'!$A$2:$A$255,"Apr-2025")=0,"",SUMIFS('Standardized Data'!$G$2:$G$255,'Standardized Data'!$B$2:$B$255,$A5,'Standardized Data'!$A$2:$A$255,"Apr-2025")) -> 2097.3099 | J5: =IFERROR(AVERAGEIFS('Standardized Data'!$H$2:$H$255,'Standardized Data'!$B$2:$B$255,$A5),"") -> -3.4218097 | K5: =IFERROR(AVERAGEIFS('Standardized Data'!$I$2:$I$255,'Standardized Data'!$B$2:$B$255,$A5),"") -> 126.05759 | L5: =IF(I5<>"",I5,IF(H5<>"",H5,IF(G5<>"",G5,IF(F5<>"",F5,IF(E5<>"",E5,IF(D5<>"",D5,"")))))) -> 2097.3099
A6: Beef Bone in | B6: =IFERROR(INDEX('Standardized Data'!$D$2:$D$255,MATCH($A6,'Standardized Data'!$B$2:$B$255,0)),"") -> Discontinued | C6: =COUNTIF('Standardized Data'!$B$2:$B$255,$A6) -> 2 | D6: =IF(SUMIFS('Standardized Data'!$G$2:$G$255,'Standardized Data'!$B$2:$B$255,$A6,'Standardized Data'!$A$2:$A$255,"Nov-2024")=0,"",SUMIFS('Standardized Data'!$G$2:$G$255,'Standardized Data'!$B$2:$B$255,$A6,'Standardized Data'!$A$2:$A$255,"Nov-2024")) -> 5073.7358 | E6: =IF(SUMIFS('Standardized Data'!$G$2:$G$255,'Standardized Data'!$B$2:$B$255,$A6,'Standardized Data'!$A$2:$A$255,"Dec-2024")=0,"",SUMIFS('Standardized Data'!$G$2:$G$255,'Standardized Data'!$B$2:$B$255,$A6,'Standardized Data'!$A$2:$A$255,"Dec-2024")) -> 5153.1849 | F6: =IF(SUMIFS('Standardized Data'!$G$2:$G$255,'Standardized Data'!$B$2:$B$255,$A6,'Standardized Data'!$A$2:$A$255,"Jan-2025")=0,"",SUMIFS('Standardized Data'!$G$2:$G$255,'Standardized Data'!$B$2:$B$255,$A6,'Standardized Data'!$A$2:$A$255,"Jan-2025")) | G6: =IF(SUMIFS('Standardized Data'!$G$2:$G$255,'Standardized Data'!$B$2:$B$255,$A6,'Standardized Data'!$A$2:$A$255,"Feb-2025")=0,"",SUMIFS('Standardized Data'!$G$2:$G$255,'Standardized Data'!$B$2:$B$255,$A6,'Standardized Data'!$A$2:$A$255,"Feb-2025")) | H6: =IF(SUMIFS('Standardized Data'!$G$2:$G$255,'Standardized Data'!$B$2:$B$255,$A6,'Standardized Data'!$A$2:$A$255,"Mar-2025")=0,"",SUMIFS('Standardized Data'!$G$2:$G$255,'Standardized Data'!$B$2:$B$255,$A6,'Standardized Data'!$A$2:$A$255,"Mar-2025")) | I6: =IF(SUMIFS('Standardized Data'!$G$2:$G$255,'Standardized Data'!$B$2:$B$255,$A6,'Standardized Data'!$A$2:$A$255,"Apr-2025")=0,"",SUMIFS('Standardized Data'!$G$2:$G$255,'Standardized Data'!$B$2:$B$255,$A6,'Standardized Data'!$A$2:$A$255,"Apr-2025")) | J6: =IFERROR(AVERAGEIFS('Standardized Data'!$H$2:$H$255,'Standardized Data'!$B$2:$B$255,$A6),"") -> 2.4017255 | K6: =IFERROR(AVERAGEIFS('Standardized Data'!$I$2:$I$255,'Standardized Data'!$B$2:$B$255,$A6),"") -> 91.99809 | L6: =IF(I6<>"",I6,IF(H6<>"",H6,IF(G6<>"",G6,IF(F6<>"",F6,IF(E6<>"",E6,IF(D6<>"",D6,"")))))) -> 5153.1849
A7: Beef Boneless | B7: =IFERROR(INDEX('Standardized Data'!$D$2:$D$255,MATCH($A7,'Standardized Data'!$B$2:$B$255,0)),"") -> Confirmed | C7: =COUNTIF('Standardized Data'!$B$2:$B$255,$A7) -> 6 | D7: =IF(SUMIFS('Standardized Data'!$G$2:$G$255,'Standardized Data'!$B$2:$B$255,$A7,'Standardized Data'!$A$2:$A$255,"Nov-2024")=0,"",SUMIFS('Standardized Data'!$G$2:$G$255,'Standardized Data'!$B$2:$B$255,$A7,'Standardized Data'!$A$2:$A$255,"Nov-2024")) -> 6001.3163 | E7: =IF(SUMIFS('Standardized Data'!$G$2:$G$255,'Standardized Data'!$B$2:$B$255,$A7,'Standardized Data'!$A$2:$A$255,"Dec-2024")=0,"",SUMIFS('Standardized Data'!$G$2:$G$255,'Standardized Data'!$B$2:$B$255,$A7,'Standardized Data'!$A$2:$A$255,"Dec-2024")) -> 6150.1829 | F7: =IF(SUMIFS('Standardized Data'!$G$2:$G$255,'Standardized Data'!$B$2:$B$255,$A7,'Standardized Data'!$A$2:$A$255,"Jan-2025")=0,"",SUMIFS('Standardized Data'!$G$2:$G$255,'Standardized Data'!$B$2:$B$255,$A7,'Standardized Data'!$A$2:$A$255,"Jan-2025")) -> 6122.5683 | G7: =IF(SUMIFS('Standardized Data'!$G$2:$G$255,'Standardized Data'!$B$2:$B$255,$A7,'Standardized Data'!$A$2:$A$255,"Feb-2025")=0,"",SUMIFS('Standardized Data'!$G$2:$G$255,'Standardized Data'!$B$2:$B$255,$A7,'Standardized Data'!$A$2:$A$255,"Feb-2025")) -> 6269.4588 | H7: =IF(SUMIFS('Standardized Data'!$G$2:$G$255,'Standardized Data'!$B$2:$B$255,$A7,'Standardized Data'!$A$2:$A$255,"Mar-2025")=0,"",SUMIFS('Standardized Data'!$G$2:$G$255,'Standardized Data'!$B$2:$B$255,$A7,'Standardized Data'!$A$2:$A$255,"Mar-2025")) -> 6523.501 | I7: =IF(SUMIFS('Standardized Data'!$G$2:$G$255,'Standardized Data'!$B$2:$B$255,$A7,'Standardized Data'!$A$2:$A$255,"Apr-2025")=0,"",SUMIFS('Standardized Data'!$G$2:$G$255,'Standardized Data'!$B$2:$B$255,$A7,'Standardized Data'!$A$2:$A$255,"Apr-2025")) -> 6544.5369 | J7: =IFERROR(AVERAGEIFS('Standardized Data'!$H$2:$H$255,'Standardized Data'!$B$2:$B$255,$A7),"") -> 1.8736114 | K7: =IFERROR(AVERAGEIFS('Standardized Data'!$I$2:$I$255,'Standardized Data'!$B$2:$B$255,$A7),"") -> 73.336427 | L7: =IF(I7<>"",I7,IF(H7<>"",H7,IF(G7<>"",G7,IF(F7<>"",F7,IF(E7<>"",E7,IF(D7<>"",D7,"")))))) -> 6544.5369
A8: Bread (sliced), 450g | B8: =IFERROR(INDEX('Standardized Data'!$D$2:$D$255,MATCH($A8,'Standardized Data'!$B$2:$B$255,0)),"") -> Likely | C8: =COUNTIF('Standardized Data'!$B$2:$B$255,$A8) -> 6 | D8: =IF(SUMIFS('Standardized Data'!$G$2:$G$255,'Standardized Data'!$B$2:$B$255,$A8,'Standardized Data'!$A$2:$A$255,"Nov-2024")=0,"",SUMIFS('Standardized Data'!$G$2:$G$255,'Standardized Data'!$B$2:$B$255,$A8,'Standardized Data'!$A$2:$A$255,"Nov-2024")) -> 1588.0267 | E8: =IF(SUMIFS('Standardized Data'!$G$2:$G$255,'Standardized Data'!$B$2:$B$255,$A8,'Standardized Data'!$A$2:$A$255,"Dec-2024")=0,"",SUMIFS('Standardized Data'!$G$2:$G$255,'Standardized Data'!$B$2:$B$255,$A8,'Standardized Data'!$A$2:$A$255,"Dec-2024")) -> 1610.8262 | F8: =IF(SUMIFS('Standardized Data'!$G$2:$G$255,'Standardized Data'!$B$2:$B$255,$A8,'Standardized Data'!$A$2:$A$255,"Jan-2025")=0,"",SUMIFS('Standardized Data'!$G$2:$G$255,'Standardized Data'!$B$2:$B$255,$A8,'Standardized Data'!$A$2:$A$255,"Jan-2025")) -> 1604.7842 | G8: =IF(SUMIFS('Standardized Data'!$G$2:$G$255,'Standardized Data'!$B$2:$B$255,$A8,'Standardized Data'!$A$2:$A$255,"Feb-2025")=0,"",SUMIFS('Standardized Data'!$G$2:$G$255,'Standardized Data'!$B$2:$B$255,$A8,'Standardized Data'!$A$2:$A$255,"Feb-2025")) -> 1633.1854 | H8: =IF(SUMIFS('Standardized Data'!$G$2:$G$255,'Standardized Data'!$B$2:$B$255,$A8,'Standardized Data'!$A$2:$A$255,"Mar-2025")=0,"",SUMIFS('Standardized Data'!$G$2:$G$255,'Standardized Data'!$B$2:$B$255,$A8,'Standardized Data'!$A$2:$A$255,"Mar-2025")) -> 1680.1747 | I8: =IF(SUMIFS('Standardized Data'!$G$2:$G$255,'Standardized Data'!$B$2:$B$255,$A8,'Standardized Data'!$A$2:$A$255,"Apr-2025")=0,"",SUMIFS('Standardized Data'!$G$2:$G$255,'Standardized Data'!$B$2:$B$255,$A8,'Standardized Data'!$A$2:$A$255,"Apr-2025")) -> 1688.3998 | J8: =IFERROR(AVERAGEIFS('Standardized Data'!$H$2:$H$255,'Standardized Data'!$B$2:$B$255,$A8),"") -> 1.8018964 | K8: =IFERROR(AVERAGEIFS('Standardized Data'!$I$2:$I$255,'Standardized Data'!$B$2:$B$255,$A8),"") -> 91.676148 | L8: =IF(I8<>"",I8,IF(H8<>"",H8,IF(G8<>"",G8,IF(F8<>"",F8,IF(E8<>"",E8,IF(D8<>"",D8,"")))))) -> 1688.3998
A9: Bread (unsliced), 450g | B9: =IFERROR(INDEX('Standardized Data'!$D$2:$D$255,MATCH($A9,'Standardized Data'!$B$2:$B$255,0)),"") -> Likely | C9: =COUNTIF('Standardized Data'!$B$2:$B$255,$A9) -> 6 | D9: =IF(SUMIFS('Standardized Data'!$G$2:$G$255,'Standardized Data'!$B$2:$B$255,$A9,'Standardized Data'!$A$2:$A$255,"Nov-2024")=0,"",SUMIFS('Standardized Data'!$G$2:$G$255,'Standardized Data'!$B$2:$B$255,$A9,'Standardized Data'!$A$2:$A$255,"Nov-2024")) -> 1486.2466 | E9: =IF(SUMIFS('Standardized Data'!$G$2:$G$255,'Standardized Data'!$B$2:$B$255,$A9,'Standardized Data'!$A$2:$A$255,"Dec-2024")=0,"",SUMIFS('Standardized Data'!$G$2:$G$255,'Standardized Data'!$B$2:$B$255,$A9,'Standardized Data'!$A$2:$A$255,"Dec-2024")) -> 1512.1275 | F9: =IF(SUMIFS('Standardized Data'!$G$2:$G$255,'Standardized Data'!$B$2:$B$255,$A9,'Standardized Data'!$A$2:$A$255,"Jan-2025")=0,"",SUMIFS('Standardized Data'!$G$2:$G$255,'Standardized Data'!$B$2:$B$255,$A9,'Standardized Data'!$A$2:$A$255,"Jan-2025")) -> 1452.983 | G9: =IF(SUMIFS('Standardized Data'!$G$2:$G$255,'Standardized Data'!$B$2:$B$255,$A9,'Standardized Data'!$A$2:$A$255,"Feb-2025")=0,"",SUMIFS('Standardized Data'!$G$2:$G$255,'Standardized Data'!$B$2:$B$255,$A9,'Standardized Data'!$A$2:$A$255,"Feb-2025")) -> 1497.4272 | H9: =IF(SUMIFS('Standardized Data'!$G$2:$G$255,'Standardized Data'!$B$2:$B$255,$A9,'Standardized Data'!$A$2:$A$255,"Mar-2025")=0,"",SUMIFS('Standardized Data'!$G$2:$G$255,'Standardized Data'!$B$2:$B$255,$A9,'Standardized Data'!$A$2:$A$255,"Mar-2025")) -> 1561.2438 | I9: =IF(SUMIFS('Standardized Data'!$G$2:$G$255,'Standardized Data'!$B$2:$B$255,$A9,'Standardized Data'!$A$2:$A$255,"Apr-2025")=0,"",SUMIFS('Standardized Data'!$G$2:$G$255,'Standardized Data'!$B$2:$B$255,$A9,'Standardized Data'!$A$2:$A$255,"Apr-2025")) -> 1547.5179 | J9: =IFERROR(AVERAGEIFS('Standardized Data'!$H$2:$H$255,'Standardized Data'!$B$2:$B$255,$A9),"") -> 2.0739804 | K9: =IFERROR(AVERAGEIFS('Standardized Data'!$I$2:$I$255,'Standardized Data'!$B$2:$B$255,$A9),"") -> 86.133272 | L9: =IF(I9<>"",I9,IF(H9<>"",H9,IF(G9<>"",G9,IF(F9<>"",F9,IF(E9<>"",E9,IF(D9<>"",D9,"")))))) -> 1547.5179
A10: Carrots, fresh | B10: =IFERROR(INDEX('Standardized Data'!$D$2:$D$255,MATCH($A10,'Standardized Data'!$B$2:$B$255,0)),"") -> New (2025) | C10: =COUNTIF('Standardized Data'!$B$2:$B$255,$A10) -> 4 | D10: =IF(SUMIFS('Standardized Data'!$G$2:$G$255,'Standardized Data'!$B$2:$B$255,$A10,'Standardized Data'!$A$2:$A$255,"Nov-2024")=0,"",SUMIFS('Standardized Data'!$G$2:$G$255,'Standardized Data'!$B$2:$B$255,$A10,'Standardized Data'!$A$2:$A$255,"Nov-2024")) | E10: =IF(SUMIFS('Standardized Data'!$G$2:$G$255,'Standardized Data'!$B$2:$B$255,$A10,'Standardized Data'!$A$2:$A$255,"Dec-2024")=0,"",SUMIFS('Standardized Data'!$G$2:$G$255,'Standardized Data'!$B$2:$B$255,$A10,'Standardized Data'!$A$2:$A$255,"Dec-2024")) | F10: =IF(SUMIFS('Standardized Data'!$G$2:$G$255,'Standardized Data'!$B$2:$B$255,$A10,'Standardized Data'!$A$2:$A$255,"Jan-2025")=0,"",SUMIFS('Standardized Data'!$G$2:$G$255,'Standardized Data'!$B$2:$B$255,$A10,'Standardized Data'!$A$2:$A$255,"Jan-2025")) -> 1787.1615 | G10: =IF(SUMIFS('Standardized Data'!$G$2:$G$255,'Standardized Data'!$B$2:$B$255,$A10,'Standardized Data'!$A$2:$A$255,"Feb-2025")=0,"",SUMIFS('Standardized Data'!$G$2:$G$255,'Standardized Data'!$B$2:$B$255,$A10,'Standardized Data'!$A$2:$A$255,"Feb-2025")) -> 1838.5928 | H10: =IF(SUMIFS('Standardized Data'!$G$2:$G$255,'Standardized Data'!$B$2:$B$255,$A10,'Standardized Data'!$A$2:$A$255,"Mar-2025")=0,"",SUMIFS('Standardized Data'!$G$2:$G$255,'Standardized Data'!$B$2:$B$255,$A10,'Standardized Data'!$A$2:$A$255,"Mar-2025")) -> 1947.0497 | I10: =IF(SUMIFS('Standardized Data'!$G$2:$G$255,'Standardized Data'!$B$2:$B$255,$A10,'Standardized Data'!$A$2:$A$255,"Apr-2025")=0,"",SUMIFS('Standardized Data'!$G$2:$G$255,'Standardized Data'!$B$2:$B$255,$A10,'Standardized Data'!$A$2:$A$255,"Apr-2025")) -> 1931.3179 | J10: =IFERROR(AVERAGEIFS('Standardized Data'!$H$2:$H$255,'Standardized Data'!$B$2:$B$255,$A10),"") -> 2.6562493 | K10: =IFERROR(AVERAGEIFS('Standardized Data'!$I$2:$I$255,'Standardized Data'!$B$2:$B$255,$A10),"") | L10: =IF(I10<>"",I10,IF(H10<>"",H10,IF(G10<>"",G10,IF(F10<>"",F10,IF(E10<>"",E10,IF(D10<>"",D10,"")))))) -> 1931.3179
A11: Cat fresh fish | B11: =IFERROR(INDEX('Standardized Data'!$D$2:$D$255,MATCH($A11,'Standardized Data'!$B$2:$B$255,0)),"") -> Confirmed | C11: =COUNTIF('Standardized Data'!$B$2:$B$255,$A11) -> 6 | D11: =IF(SUMIFS('Standardized Data'!$G$2:$G$255,'Standardized Data'!$B$2:$B$255,$A11,'Standardized Data'!$A$2:$A$255,"Nov-2024")=0,"",SUMIFS('Standardized Data'!$G$2:$G$255,'Standardized Data'!$B$2:$B$255,$A11,'Standardized Data'!$A$2:$A$255,"Nov-2024")) -> 4259.987 | E11: =IF(SUMIFS('Standardized Data'!$G$2:$G$255,'Standardized Data'!$B$2:$B$255,$A11,'Standardized Data'!$A$2:$A$255,"Dec-2024")=0,"",SUMIFS('Standardized Data'!$G$2:$G$255,'Standardized Data'!$B$2:$B$255,$A11,'Standardized Data'!$A$2:$A$255,"Dec-2024")) -> 4347.4446 | F11: =IF(SUMIFS('Standardized Data'!$G$2:$G$255,'Standardized Data'!$B$2:$B$255,$A11,'Standardized Data'!$A$2:$A$255,"Jan-2025")=0,"",SUMIFS('Standardized Data'!$G$2:$G$255,'Standardized Data'!$B$2:$B$255,$A11,'Standardized Data'!$A$2:$A$255,"Jan-2025")) -> 5226.8706 | G11: =IF(SUMIFS('Standardized Data'!$G$2:$G$255,'Standardized Data'!$B$2:$B$255,$A11,'Standardized Data'!$A$2:$A$255,"Feb-2025")=0,"",SUMIFS('Standardized Data'!$G$2:$G$255,'Standardized Data'!$B$2:$B$255,$A11,'Standardized Data'!$A$2:$A$255,"Feb-2025")) -> 5284.3595 | H11: =IF(SUMIFS('Standardized Data'!$G$2:$G$255,'Standardized Data'!$B$2:$B$255,$A11,'Standardized Data'!$A$2:$A$255,"Mar-2025")=0,"",SUMIFS('Standardized Data'!$G$2:$G$255,'Standardized Data'!$B$2:$B$255,$A11,'Standardized Data'!$A$2:$A$255,"Mar-2025")) -> 5507.1099 | I11: =IF(SUMIFS('Standardized Data'!$G$2:$G$255,'Standardized Data'!$B$2:$B$255,$A11,'Standardized Data'!$A$2:$A$255,"Apr-2025")=0,"",SUMIFS('Standardized Data'!$G$2:$G$255,'Standardized Data'!$B$2:$B$255,$A11,'Standardized Data'!$A$2:$A$255,"Apr-2025")) -> 5572.4934 | J11: =IFERROR(AVERAGEIFS('Standardized Data'!$H$2:$H$255,'Standardized Data'!$B$2:$B$255,$A11),"") -> 5.2442352 | K11: =IFERROR(AVERAGEIFS('Standardized Data'!$I$2:$I$255,'Standardized Data'!$B$2:$B$255,$A11),"") -> 89.230786 | L11: =IF(I11<>"",I11,IF(H11<>"",H11,IF(G11<>"",G11,IF(F11<>"",F11,IF(E11<>"",E11,IF(D11<>"",D11,"")))))) -> 5572.4934
A12: Catfish :dried | B12: =IFERROR(INDEX('Standardized Data'!$D$2:$D$255,MATCH($A12,'Standardized Data'!$B$2:$B$255,0)),"") -> Discontinued | C12: =COUNTIF('Standardized Data'!$B$2:$B$255,$A12) -> 2 | D12: =IF(SUMIFS('Standardized Data'!$G$2:$G$255,'Standardized Data'!$B$2:$B$255,$A12,'Standardized Data'!$A$2:$A$255,"Nov-2024")=0,"",SUMIFS('Standardized Data'!$G$2:$G$255,'Standardized Data'!$B$2:$B$255,$A12,'Standardized Data'!$A$2:$A$255,"Nov-2024")) -> 5787.7445 | E12: =IF(SUMIFS('Standardized Data'!$G$2:$G$255,'Standardized Data'!$B$2:$B$255,$A12,'Standardized Data'!$A$2:$A$255,"Dec-2024")=0,"",SUMIFS('Standardized Data'!$G$2:$G$255,'Standardized Data'!$B$2:$B$255,$A12,'Standardized Data'!$A$2:$A$255,"Dec-2024")) -> 6044.0788 | F12: =IF(SUMIFS('Standardized Data'!$G$2:$G$255,'Standardized Data'!$B$2:$B$255,$A12,'Standardized Data'!$A$2:$A$255,"Jan-2025")=0,"",SUMIFS('Standardized Data'!$G$2:$G$255,'Standardized Data'!$B$2:$B$255,$A12,'Standardized Data'!$A$2:$A$255,"Jan-2025")) | G12: =IF(SUMIFS('Standardized Data'!$G$2:$G$255,'Standardized Data'!$B$2:$B$255,$A12,'Standardized Data'!$A$2:$A$255,"Feb-2025")=0,"",SUMIFS('Standardized Data'!$G$2:$G$255,'Standardized Data'!$B$2:$B$255,$A12,'Standardized Data'!$A$2:$A$255,"Feb-2025")) | H12: =IF(SUMIFS('Standardized Data'!$G$2:$G$255,'Standardized Data'!$B$2:$B$255,$A12,'Standardized Data'!$A$2:$A$255,"Mar-2025")=0,"",SUMIFS('Standardized Data'!$G$2:$G$255,'Standardized Data'!$B$2:$B$255,$A12,'Standardized Data'!$A$2:$A$255,"Mar-2025")) | I12: =IF(SUMIFS('Standardized Data'!$G$2:$G$255,'Standardized Data'!$B$2:$B$255,$A12,'Standardized Data'!$A$2:$A$255,"Apr-2025")=0,"",SUMIFS('Standardized Data'!$G$2:$G$255,'Standardized Data'!$B$2:$B$255,$A12,'Standardized Data'!$A$2:$A$255,"Apr-2025")) | J12: =IFERROR(AVERAGEIFS('Standardized Data'!$H$2:$H$255,'Standardized Data'!$B$2:$B$255,$A12),"") -> 4.1556295 | K12: =IFERROR(AVERAGEIFS('Standardized Data'!$I$2:$I$255,'Standardized Data'!$B$2:$B$255,$A12),"") -> 78.326962 | L12: =IF(I12<>"",I12,IF(H12<>"",H12,IF(G12<>"",G12,IF(F12<>"",F12,IF(E12<>"",E12,IF(D12<>"",D12,"")))))) -> 6044.0788
A13: Catfish Smoked | B13: =IFERROR(INDEX('Standardized Data'!$D$2:$D$255,MATCH($A13,'Standardized Data'!$B$2:$B$255,0)),"") -> Discontinued | C13: =COUNTIF('Standardized Data'!$B$2:$B$255,$A13) -> 2 | D13: =IF(SUMIFS('Standardized Data'!$G$2:$G$255,'Standardized Data'!$B$2:$B$255,$A13,'Standardized Data'!$A$2:$A$255,"Nov-2024")=0,"",SUMIFS('Standardized Data'!$G$2:$G$255,'Standardized Data'!$B$2:$B$255,$A13,'Standardized Data'!$A$2:$A$255,"Nov-2024")) -> 4352.7683 | E13: =IF(SUMIFS('Standardized Data'!$G$2:$G$255,'Standardized Data'!$B$2:$B$255,$A13,'Standardized Data'!$A$2:$A$255,"Dec-2024")=0,"",SUMIFS('Standardized Data'!$G$2:$G$255,'Standardized Data'!$B$2:$B$255,$A13,'Standardized Data'!$A$2:$A$255,"Dec-2024")) -> 4475.0964 | F13: =IF(SUMIFS('Standardized Data'!$G$2:$G$255,'Standardized Data'!$B$2:$B$255,$A13,'Standardized Data'!$A$2:$A$255,"Jan-2025")=0,"",SUMIFS('Standardized Data'!$G$2:$G$255,'Standardized Data'!$B$2:$B$255,$A13,'Standardized Data'!$A$2:$A$255,"Jan-2025")) | G13: =IF(SUMIFS('Standardized Data'!$G$2:$G$255,'Standardized Data'!$B$2:$B$255,$A13,'Standardized Data'!$A$2:$A$255,"Feb-2025")=0,"",SUMIFS('Standardized Data'!$G$2:$G$255,'Standardized Data'!$B$2:$B$255,$A13,'Standardized Data'!$A$2:$A$255,"Feb-2025")) | H13: =IF(SUMIFS('Standardized Data'!$G$2:$G$255,'Standardized Data'!$B$2:$B$255,$A13,'Standardized Data'!$A$2:$A$255,"Mar-2025")=0,"",SUMIFS('Standardized Data'!$G$2:$G$255,'Standardized Data'!$B$2:$B$255,$A13,'Standardized Data'!$A$2:$A$255,"Mar-2025")) | I13: =IF(SUMIFS('Standardized Data'!$G$2:$G$255,'Standardized Data'!$B$2:$B$255,$A13,'Standardized Data'!$A$2:$A$255,"Apr-2025")=0,"",SUMIFS('Standardized Data'!$G$2:$G$255,'Standardized Data'!$B$2:$B$255,$A13,'Standardized Data'!$A$2:$A$255,"Apr-2025")) | J13: =IFERROR(AVERAGEIFS('Standardized Data'!$H$2:$H$255,'Standardized Data'!$B$2:$B$255,$A13),"") -> 2.7351371 | K13: =IFERROR(AVERAGEIFS('Standardized Data'!$I$2:$I$255,'Standardized Data'!$B$2:$B$255,$A13),"") -> 55.252703 | L13: =IF(I13<>"",I13,IF(H13<>"",H13,IF(G13<>"",G13,IF(F13<>"",F13,IF(E13<>"",E13,IF(D13<>"",D13,"")))))) -> 4475.0964
... A53: Yam Tuber | B53: =IFERROR(INDEX('Standardized Data'!$D$2:$D$255,MATCH($A53,'Standardized Data'!$B$2:$B$255,0)),"") -> Confirmed | C53: =COUNTIF('Standardized Data'!$B$2:$B$255,$A53) -> 6 | D53: =IF(SUMIFS('Standardized Data'!$G$2:$G$255,'Standardized Data'!$B$2:$B$255,$A53,'Standardized Data'!$A$2:$A$255,"Nov-2024")=0,"",SUMIFS('Standardized Data'!$G$2:$G$255,'Standardized Data'!$B$2:$B$255,$A53,'Standardized Data'!$A$2:$A$255,"Nov-2024")) -> 1836.0085 | E53: =IF(SUMIFS('Standardized Data'!$G$2:$G$255,'Standardized Data'!$B$2:$B$255,$A53,'Standardized Data'!$A$2:$A$255,"Dec-2024")=0,"",SUMIFS('Standardized Data'!$G$2:$G$255,'Standardized Data'!$B$2:$B$255,$A53,'Standardized Data'!$A$2:$A$255,"Dec-2024")) -> 1905.901 | F53: =IF(SUMIFS('Standardized Data'!$G$2:$G$255,'Standardized Data'!$B$2:$B$255,$A53,'Standardized Data'!$A$2:$A$255,"Jan-2025")=0,"",SUMIFS('Standardized Data'!$G$2:$G$255,'Standardized Data'!$B$2:$B$255,$A53,'Standardized Data'!$A$2:$A$255,"Jan-2025")) -> 1991.3299 | G53: =IF(SUMIFS('Standardized Data'!$G$2:$G$255,'Standardized Data'!$B$2:$B$255,$A53,'Standardized Data'!$A$2:$A$255,"Feb-2025")=0,"",SUMIFS('Standardized Data'!$G$2:$G$255,'Standardized Data'!$B$2:$B$255,$A53,'Standardized Data'!$A$2:$A$255,"Feb-2025")) -> 2022.0329 | H53: =IF(SUMIFS('Standardized Data'!$G$2:$G$255,'Standardized Data'!$B$2:$B$255,$A53,'Standardized Data'!$A$2:$A$255,"Mar-2025")=0,"",SUMIFS('Standardized Data'!$G$2:$G$255,'Standardized Data'!$B$2:$B$255,$A53,'Standardized Data'!$A$2:$A$255,"Mar-2025")) -> 2141.13 | I53: =IF(SUMIFS('Standardized Data'!$G$2:$G$255,'Standardized Data'!$B$2:$B$255,$A53,'Standardized Data'!$A$2:$A$255,"Apr-2025")=0,"",SUMIFS('Standardized Data'!$G$2:$G$255,'Standardized Data'!$B$2:$B$255,$A53,'Standardized Data'!$A$2:$A$255,"Apr-2025")) -> 2240.0838 | J53: =IFERROR(AVERAGEIFS('Standardized Data'!$H$2:$H$255,'Standardized Data'!$B$2:$B$255,$A53),"") -> 4.6649022 | K53: =IFERROR(AVERAGEIFS('Standardized Data'!$I$2:$I$255,'Standardized Data'!$B$2:$B$255,$A53),"") -> 114.98585 | L53: =IF(I53<>"",I53,IF(H53<>"",H53,IF(G53<>"",G53,IF(F53<>"",F53,IF(E53<>"",E53,IF(D53<>"",D53,"")))))) -> 2240.0838

Sheet State Summary
A1: State | B1: Times Highest | C1: Times Lowest | D1: Avg Price When Highest | E1: Avg Price When Lowest
A2: Abia | B2: =COUNTIF('Standardized Data'!$K$2:$K$255,$A2) -> 9 | C2: =COUNTIF('Standardized Data'!$N$2:$N$255,$A2) -> 2 | D2: =IFERROR(AVERAGEIF('Standardized Data'!$K$2:$K$255,$A2,'Standardized Data'!$L$2:$L$255),"") -> 5523.34 | E2: =IFERROR(AVERAGEIF('Standardized Data'!$N$2:$N$255,$A2,'Standardized Data'!$O$2:$O$255),"") -> 3063.96
A3: Abuja | B3: =COUNTIF('Standardized Data'!$K$2:$K$255,$A3) -> 7 | C3: =COUNTIF('Standardized Data'!$N$2:$N$255,$A3) -> 10 | D3: =IFERROR(AVERAGEIF('Standardized Data'!$K$2:$K$255,$A3,'Standardized Data'!$L$2:$L$255),"") -> 3234.5814 | E3: =IFERROR(AVERAGEIF('Standardized Data'!$N$2:$N$255,$A3,'Standardized Data'!$O$2:$O$255),"") -> 1714.899
A4: Adamawa | B4: =COUNTIF('Standardized Data'!$K$2:$K$255,$A4) -> 3 | C4: =COUNTIF('Standardized Data'!$N$2:$N$255,$A4) -> 21 | D4: =IFERROR(AVERAGEIF('Standardized Data'!$K$2:$K$255,$A4,'Standardized Data'!$L$2:$L$255),"") -> 2679 | E4: =IFERROR(AVERAGEIF('Standardized Data'!$N$2:$N$255,$A4,'Standardized Data'!$O$2:$O$255),"") -> 1744.0476
A5: Akwa Ibom | B5: =COUNTIF('Standardized Data'!$K$2:$K$255,$A5) -> 11 | C5: =COUNTIF('Standardized Data'!$N$2:$N$255,$A5) -> 1 | D5: =IFERROR(AVERAGEIF('Standardized Data'!$K$2:$K$255,$A5,'Standardized Data'!$L$2:$L$255),"") -> 4831.7627 | E5: =IFERROR(AVERAGEIF('Standardized Data'!$N$2:$N$255,$A5,'Standardized Data'!$O$2:$O$255),"") -> 4576.03
A6: Anambra | B6: =COUNTIF('Standardized Data'!$K$2:$K$255,$A6) -> 6 | C6: =COUNTIF('Standardized Data'!$N$2:$N$255,$A6) -> 1 | D6: =IFERROR(AVERAGEIF('Standardized Data'!$K$2:$K$255,$A6,'Standardized Data'!$L$2:$L$255),"") -> 2959.575 | E6: =IFERROR(AVERAGEIF('Standardized Data'!$N$2:$N$255,$A6,'Standardized Data'!$O$2:$O$255),"") -> 3650.97
A7: Bauchi | B7: =COUNTIF('Standardized Data'!$K$2:$K$255,$A7) -> 3 | C7: =COUNTIF('Standardized Data'!$N$2:$N$255,$A7) -> 5 | D7: =IFERROR(AVERAGEIF('Standardized Data'!$K$2:$K$255,$A7,'Standardized Data'!$L$2:$L$255),"") -> 2492.0167 | E7: =IFERROR(AVERAGEIF('Standardized Data'!$N$2:$N$255,$A7,'Standardized Data'!$O$2:$O$255),"") -> 2340.084
A8: Bayelsa | B8: =COUNTIF('Standardized Data'!$K$2:$K$255,$A8) -> 8 | C8: =COUNTIF('Standardized Data'!$N$2:$N$255,$A8) -> 6 | D8: =IFERROR(AVERAGEIF('Standardized Data'!$K$2:$K$255,$A8,'Standardized Data'!$L$2:$L$255),"") -> 3253.4825 | E8: =IFERROR(AVERAGEIF('Standardized Data'!$N$2:$N$255,$A8,'Standardized Data'!$O$2:$O$255),"") -> 3084.9867
A9: Benue | B9: =COUNTIF('Standardized Data'!$K$2:$K$255,$A9) -> 4 | C9: =COUNTIF('Standardized Data'!$N$2:$N$255,$A9) -> 16 | D9: =IFERROR(AVERAGEIF('Standardized Data'!$K$2:$K$255,$A9,'Standardized Data'!$L$2:$L$255),"") -> 8281.5175 | E9: =IFERROR(AVERAGEIF('Standardized Data'!$N$2:$N$255,$A9,'Standardized Data'!$O$2:$O$255),"") -> 1839.5137
A10: Borno | B10: =COUNTIF('Standardized Data'!$K$2:$K$255,$A10) -> 2 | C10: =COUNTIF('Standardized Data'!$N$2:$N$255,$A10) -> 15 | D10: =IFERROR(AVERAGEIF('Standardized Data'!$K$2:$K$255,$A10,'Standardized Data'!$L$2:$L$255),"") -> 3342.125 | E10: =IFERROR(AVERAGEIF('Standardized Data'!$N$2:$N$255,$A10,'Standardized Data'!$O$2:$O$255),"") -> 1396.33
